Workbook

Sheet Choose Benchmark
A1: Choose one benchmark
A2: Benchmark | B2: SWE-Bench Pro
A3: Models are kept down the left side. Pick a benchmark from B2; the table, chart, and explanation boxes update.
A5: Model | B5: Score | C5: Unit | D5: Source
A6: ChatGPT 5.5 | B6: =IFERROR(INDEX('Benchmark Matrix'!$B$2:$AV$9,MATCH(A6,'Benchmark Matrix'!$A$2:$A$9,0),MATCH($B$2,'Benchmark Matrix'!$B$1:$AV$1,0)),"") | C6: =IF($B6="","",IFERROR(INDEX('Benchmark Metadata'!$C$2:$C$48,MATCH($B$2,'Benchmark Metadata'!$A$2:$A$48,0)),"")) | D6: =IF($B6="","",IFERROR(INDEX('Source Matrix'!$B$2:$AV$9,MATCH(A6,'Source Matrix'!$A$2:$A$9,0),MATCH($B$2,'Source Matrix'!$B$1:$AV$1,0)),""))
A7: ChatGPT 5.3 Codex | B7: =IFERROR(INDEX('Benchmark Matrix'!$B$2:$AV$9,MATCH(A7,'Benchmark Matrix'!$A$2:$A$9,0),MATCH($B$2,'Benchmark Matrix'!$B$1:$AV$1,0)),"") | C7: =IF($B7="","",IFERROR(INDEX('Benchmark Metadata'!$C$2:$C$48,MATCH($B$2,'Benchmark Metadata'!$A$2:$A$48,0)),"")) | D7: =IF($B7="","",IFERROR(INDEX('Source Matrix'!$B$2:$AV$9,MATCH(A7,'Source Matrix'!$A$2:$A$9,0),MATCH($B$2,'Source Matrix'!$B$1:$AV$1,0)),""))
A8: Claude Opus 4.7 | B8: =IFERROR(INDEX('Benchmark Matrix'!$B$2:$AV$9,MATCH(A8,'Benchmark Matrix'!$A$2:$A$9,0),MATCH($B$2,'Benchmark Matrix'!$B$1:$AV$1,0)),"") | C8: =IF($B8="","",IFERROR(INDEX('Benchmark Metadata'!$C$2:$C$48,MATCH($B$2,'Benchmark Metadata'!$A$2:$A$48,0)),"")) | D8: =IF($B8="","",IFERROR(INDEX('Source Matrix'!$B$2:$AV$9,MATCH(A8,'Source Matrix'!$A$2:$A$9,0),MATCH($B$2,'Source Matrix'!$B$1:$AV$1,0)),""))
A9: Claude Sonnet 4.6 | B9: =IFERROR(INDEX('Benchmark Matrix'!$B$2:$AV$9,MATCH(A9,'Benchmark Matrix'!$A$2:$A$9,0),MATCH($B$2,'Benchmark Matrix'!$B$1:$AV$1,0)),"") | C9: =IF($B9="","",IFERROR(INDEX('Benchmark Metadata'!$C$2:$C$48,MATCH($B$2,'Benchmark Metadata'!$A$2:$A$48,0)),"")) | D9: =IF($B9="","",IFERROR(INDEX('Source Matrix'!$B$2:$AV$9,MATCH(A9,'Source Matrix'!$A$2:$A$9,0),MATCH($B$2,'Source Matrix'!$B$1:$AV$1,0)),""))
A10: MiniMax M2.7 | B10: =IFERROR(INDEX('Benchmark Matrix'!$B$2:$AV$9,MATCH(A10,'Benchmark Matrix'!$A$2:$A$9,0),MATCH($B$2,'Benchmark Matrix'!$B$1:$AV$1,0)),"") | C10: =IF($B10="","",IFERROR(INDEX('Benchmark Metadata'!$C$2:$C$48,MATCH($B$2,'Benchmark Metadata'!$A$2:$A$48,0)),"")) | D10: =IF($B10="","",IFERROR(INDEX('Source Matrix'!$B$2:$AV$9,MATCH(A10,'Source Matrix'!$A$2:$A$9,0),MATCH($B$2,'Source Matrix'!$B$1:$AV$1,0)),""))
A11: Kimi K2.6 | B11: =IFERROR(INDEX('Benchmark Matrix'!$B$2:$AV$9,MATCH(A11,'Benchmark Matrix'!$A$2:$A$9,0),MATCH($B$2,'Benchmark Matrix'!$B$1:$AV$1,0)),"") | C11: =IF($B11="","",IFERROR(INDEX('Benchmark Metadata'!$C$2:$C$48,MATCH($B$2,'Benchmark Metadata'!$A$2:$A$48,0)),"")) | D11: =IF($B11="","",IFERROR(INDEX('Source Matrix'!$B$2:$AV$9,MATCH(A11,'Source Matrix'!$A$2:$A$9,0),MATCH($B$2,'Source Matrix'!$B$1:$AV$1,0)),""))
A12: DeepSeek V4-Pro Max | B12: =IFERROR(INDEX('Benchmark Matrix'!$B$2:$AV$9,MATCH(A12,'Benchmark Matrix'!$A$2:$A$9,0),MATCH($B$2,'Benchmark Matrix'!$B$1:$AV$1,0)),"") | C12: =IF($B12="","",IFERROR(INDEX('Benchmark Metadata'!$C$2:$C$48,MATCH($B$2,'Benchmark Metadata'!$A$2:$A$48,0)),"")) | D12: =IF($B12="","",IFERROR(INDEX('Source Matrix'!$B$2:$AV$9,MATCH(A12,'Source Matrix'!$A$2:$A$9,0),MATCH($B$2,'Source Matrix'!$B$1:$AV$1,0)),""))
A13: GLM-5.1 | B13: =IFERROR(INDEX('Benchmark Matrix'!$B$2:$AV$9,MATCH(A13,'Benchmark Matrix'!$A$2:$A$9,0),MATCH($B$2,'Benchmark Matrix'!$B$1:$AV$1,0)),"") | C13: =IF($B13="","",IFERROR(INDEX('Benchmark Metadata'!$C$2:$C$48,MATCH($B$2,'Benchmark Metadata'!$A$2:$A$48,0)),"")) | D13: =IF($B13="","",IFERROR(INDEX('Source Matrix'!$B$2:$AV$9,MATCH(A13,'Source Matrix'!$A$2:$A$9,0),MATCH($B$2,'Source Matrix'!$B$1:$AV$1,0)),""))
A16: What is this benchmark?
A17: =IFERROR(INDEX('Benchmark Metadata'!$E$2:$E$48,MATCH($B$2,'Benchmark Metadata'!$A$2:$A$48,0)),"")
A21: Explain it for an 11-year-old
A22: =IFERROR(INDEX('Benchmark Metadata'!$F$2:$F$48,MATCH($B$2,'Benchmark Metadata'!$A$2:$A$48,0)),"")
A26: Top score example
A27: =IFERROR(INDEX('Benchmark Metadata'!$I$2:$I$48,MATCH($B$2,'Benchmark Metadata'!$A$2:$A$48,0)),"")
A31: Similar tests and differences
A32: =IFERROR(INDEX('Benchmark Metadata'!$H$2:$H$48,MATCH($B$2,'Benchmark Metadata'!$A$2:$A$48,0)),"")

Sheet Summary
A1: What changed | B1: Details
A2: Benchmark-first layout | B2: Use Choose Benchmark to pick one benchmark at a time. The models stay down the left side, with a live bar chart.
A3: OpenAI naming | B3: The OpenAI rows are labeled ChatGPT 5.5 and ChatGPT 5.3 Codex.
A4: Plain-English boxes | B4: Each benchmark has wide explanation boxes: what it is, explain for 11, top-score example, and similar-test differences.
A5: Missing scores | B5: Blank cells mean no comparable public value was found in the selected source set, not a zero score.

Sheet Benchmark Metadata
A1: Benchmark | B1: Category | C1: Unit | D1: Difficulty Ladder | E1: What is | F1: Explain for 11 | G1: Top-score example | H1: Similar tests and differences | I1: Top score note
A2: GSM8K | B2: Math & Reasoning | C2: % EM | D2: 1 - Starter math | E2: Grade-school arithmetic word problems. | F2: Story problems: read the sentence, set up the numbers, and calculate the answer. | G2: multi-step school word problems with clean arithmetic | H2: Easier than MATH, AIME, HMMT, and IMO-style tests. | I2: Top available score here: DeepSeek V4-Pro Max at 92.6 % EM. At that level, the model is solving multi-step school word problems with clean arithmetic.
A3: HumanEval | B3: Coding | C3: % pass@1 | D3: 1 - Starter coding | E3: Small Python function-writing tasks checked by hidden tests. | F3: Write one short function, then the computer tries secret examples to see if it works. | G3: basic Python functions such as list cleanup, string logic, or simple algorithms | H3: Simpler and older than LiveCodeBench; much smaller than SWE-Bench. | I3: Top available score here: DeepSeek V4-Pro Max at 76.8 % pass@1. At that level, the model is solving basic Python functions such as list cleanup, string logic, or simple algorithms.
A4: SimpleQA-Verified | B4: Math & Reasoning | C4: % pass | D4: 1 - Starter facts | E4: Short factual questions with verified answers. | F4: A fact-check quiz: answer clearly and do not make things up. | G4: straight factual questions where accuracy matters more than style | H4: Unlike BrowseComp, the answer should not require a long web hunt. | I4: Top available score here: DeepSeek V4-Pro Max at 57.9 % pass. At that level, the model is solving straight factual questions where accuracy matters more than style.
A5: MATH | B5: Math & Reasoning | C5: % EM | D5: 2 - School contest math | E5: Competition-style math problems covering algebra, geometry, counting, and number theory. | F5: Hard school math puzzles where one missed step ruins the answer. | G5: contest math that needs several steps, not just arithmetic | H5: Harder than GSM8K; easier than AIME/HMMT/IMO and FrontierMath. | I5: Top available score here: DeepSeek V4-Pro Max at 64.5 % EM. At that level, the model is solving contest math that needs several steps, not just arithmetic.
A6: MMLU-Pro | B6: Math & Reasoning | C6: % EM | D6: 2 - Broad knowledge | E6: A harder version of MMLU with professional and academic multiple-choice questions. | F6: A big quiz across school and work subjects, but the questions try to trick shallow guessing. | G6: multi-subject reasoning across science, law, medicine, and humanities | H6: Broader than GPQA, which focuses on expert science. | I6: Top available score here: DeepSeek V4-Pro Max at 87.5 % EM. At that level, the model is solving multi-subject reasoning across science, law, medicine, and humanities.
A7: MMMLU | B7: Writing & Knowledge | C7: score | D7: 2 - Multilingual knowledge | E7: A multilingual MMLU-style benchmark for knowledge across languages. | F7: The same big school quiz idea, but not only in English. | G7: knowledge questions in multiple languages | H7: Related to GMMLU and MILU; these compare language coverage more than coding power. | I7: No comparable public score is recorded in this workbook yet. The guide entry is included so you can track it when a model card or leaderboard publishes scores.
A8: GMMLU English | B8: Writing & Knowledge | C8: score | D8: 2 - Multilingual knowledge | E8: The English slice of a global MMLU-style benchmark. | F8: The English version of a world knowledge quiz. | G8: English-language academic and professional knowledge questions | H8: Use beside low-resource averages to see whether a model is only strong in major languages. | I8: No comparable public score is recorded in this workbook yet. The guide entry is included so you can track it when a model card or leaderboard publishes scores.
A9: GMMLU low-resource average | B9: Writing & Knowledge | C9: score | D9: 2 - Multilingual knowledge | E9: Average performance across lower-resource languages. | F9: A test of whether the AI still helps in languages with less training data online. | G9: knowledge questions in languages with fewer public training examples | H9: More about language fairness than raw reasoning difficulty. | I9: No comparable public score is recorded in this workbook yet. The guide entry is included so you can track it when a model card or leaderboard publishes scores.
A10: MILU average | B10: Writing & Knowledge | C10: score | D10: 2 - Multilingual knowledge | E10: A multilingual language-understanding average. | F10: Another world-language report card for general knowledge. | G10: general knowledge and reasoning across languages | H10: Similar to GMMLU; compare exact datasets before ranking models. | I10: No comparable public score is recorded in this workbook yet. The guide entry is included so you can track it when a model card or leaderboard publishes scores.
A11: LiveCodeBench v6 | B11: Coding | C11: % pass | D11: 2 - Current coding | E11: Fresh programming contest-style tasks designed to reduce memorization. | F11: A newer coding contest where the model cannot just remember old answers. | G11: algorithmic coding problems with hidden tests | H11: More current than HumanEval; not as project-like as SWE-Bench. | I11: Top available score here: DeepSeek V4-Pro Max at 93.5 % pass. At that level, the model is solving algorithmic coding problems with hidden tests.
A12: OJBench Python | B12: Coding | C12: % pass | D12: 2 - Current coding | E12: Online-judge Python programming tasks. | F12: Coding contest puzzles where the answer must pass lots of hidden cases. | G12: Python algorithm puzzles with strict pass/fail tests | H12: Close to LiveCodeBench, but focused on online-judge style Python. | I12: Top available score here: Kimi K2.6 at 60.6 % pass. At that level, the model is solving Python algorithm puzzles with strict pass/fail tests.
... A48: CyberGym | B48: Agentic & Other | C48: % score | D48: 5 - Cybersecurity | E48: Cybersecurity challenge tasks. | F48: A computer-security obstacle course for finding and fixing digital weaknesses. | G48: security tasks such as vulnerability analysis and challenge solving | H48: Specialized domain test; not a general writing or math benchmark. | I48: Top available score here: ChatGPT 5.5 at 81.8 % score. At that level, the model is solving security tasks such as vulnerability analysis and challenge solving.

Sheet Benchmark List
A1: GSM8K
A2: HumanEval
A3: SimpleQA-Verified
A4: MATH
A5: MMLU-Pro
A6: MMMLU
A7: GMMLU English
A8: GMMLU low-resource average
A9: MILU average
A10: LiveCodeBench v6
A11: OJBench Python
A12: SciCode
... A47: CyberGym

Sheet Benchmark Matrix
A1: Model | B1: GSM8K | C1: HumanEval | D1: SimpleQA-Verified | E1: MATH | F1: MMLU-Pro | G1: MMMLU | H1: GMMLU English | I1: GMMLU low-resource average | J1: MILU average | K1: LiveCodeBench v6 | L1: OJBench Python | M1: SciCode | N1: Terminal-Bench 2.0 | O1: SWE-Bench Verified | P1: SWE-Bench Pro | Q1: SWE-Bench Multilingual | R1: Multi SWE Bench | S1: SWE-Lancer IC Diamond | T1: NL2Repo | U1: VIBE-Pro | V1: Codeforces | W1: GPQA-Diamond | X1: AIME 2026 | Y1: HMMT 2025 Nov | Z1: HMMT 2026 Feb | AA1: IMO-AnswerBench | AB1: FrontierMath Tier 1-3 | AC1: FrontierMath Tier 4 | AD1: HLE | AE1: HLE w/ tools | AF1: ARC-AGI-2 Verified | AG1: GDPval | AH1: GDPval-AA | AI1: Finance Agent | AJ1: MMMU-Pro | AK1: MMMU-Pro w/ tools | AL1: OSWorld-Verified | AM1: BrowseComp | AN1: BrowseComp w/ context management | AO1: DeepSearchQA | AP1: Toolathlon | AQ1: Tool-Decathlon | AR1: MCP-Atlas Public | AS1: tau3-Bench | AT1: MM Claw | AU1: MLE Bench Lite | AV1: CyberGym
A2: ChatGPT 5.5 | N2: 82.7 | P2: 58.6 | AB2: 51.7 | AC2: 35.4 | AG2: 84.9 | AL2: 78.7 | AM2: 84.4 | AP2: 55.6 | AV2: 81.8
A3: ChatGPT 5.3 Codex | N3: 77.3 | P3: 56.8 | S3: 81.4 | AG3: 70.9 | AL3: 64.7 | AV3: 77.6
A4: Claude Opus 4.7 | N4: 69.4 | O4: 87.6 | P4: 64.3 | W4: 94.2 | X4: 90 | AB4: 43.8 | AC4: 22.9 | AE4: 54.7 | AG4: 80.3 | AH4: 1753 | AL4: 78 | AM4: 79.3 | AR4: 77.3 | AV4: 73.1
A5: Claude Sonnet 4.6 | N5: 59.1 | O5: 79.6 | AH5: 1674
A6: MiniMax M2.7 | N6: 57 | P6: 56.22 | Q6: 76.5 | R6: 52.7 | T6: 39.8 | U6: 55.6 | AH6: 1495 | AP6: 46.3 | AT6: 62.7 | AU6: 66.6
A7: Kimi K2.6 | K7: 89.6 | L7: 60.6 | M7: 52.2 | N7: 66.7 | O7: 80.2 | P7: 58.6 | Q7: 76.7 | W7: 90.5 | X7: 96.4 | Z7: 92.7 | AA7: 86 | AD7: 34.7 | AE7: 54 | AH7: 1482 | AL7: 73.1 | AM7: 83.2 | AO7: 92.5 | AP7: 50
A8: DeepSeek V4-Pro Max | B8: 92.6 | C8: 76.8 | D8: 57.9 | E8: 64.5 | F8: 87.5 | K8: 93.5 | N8: 67.9 | O8: 80.6 | P8: 55.4 | Q8: 76.2 | V8: 3206 | W8: 90.1 | Z8: 95.2 | AA8: 89.8 | AD8: 37.7 | AE8: 48.2 | AH8: 1554 | AM8: 83.4 | AP8: 51.8 | AR8: 73.6
A9: GLM-5.1 | N9: 63.5 | P9: 58.4 | T9: 42.7 | W9: 86.2 | X9: 95.3 | Y9: 94 | Z9: 82.6 | AA9: 83.8 | AD9: 31 | AE9: 52.3 | AH9: 1535 | AM9: 68 | AN9: 79.3 | AQ9: 40.7 | AR9: 71.8 | AS9: 70.6 | AV9: 68.7

Sheet Source Matrix
A1: Model | B1: GSM8K | C1: HumanEval | D1: SimpleQA-Verified | E1: MATH | F1: MMLU-Pro | G1: MMMLU | H1: GMMLU English | I1: GMMLU low-resource average | J1: MILU average | K1: LiveCodeBench v6 | L1: OJBench Python | M1: SciCode | N1: Terminal-Bench 2.0 | O1: SWE-Bench Verified | P1: SWE-Bench Pro | Q1: SWE-Bench Multilingual | R1: Multi SWE Bench | S1: SWE-Lancer IC Diamond | T1: NL2Repo | U1: VIBE-Pro | V1: Codeforces | W1: GPQA-Diamond | X1: AIME 2026 | Y1: HMMT 2025 Nov | Z1: HMMT 2026 Feb | AA1: IMO-AnswerBench | AB1: FrontierMath Tier 1-3 | AC1: FrontierMath Tier 4 | AD1: HLE | AE1: HLE w/ tools | AF1: ARC-AGI-2 Verified | AG1: GDPval | AH1: GDPval-AA | AI1: Finance Agent | AJ1: MMMU-Pro | AK1: MMMU-Pro w/ tools | AL1: OSWorld-Verified | AM1: BrowseComp | AN1: BrowseComp w/ context management | AO1: DeepSearchQA | AP1: Toolathlon | AQ1: Tool-Decathlon | AR1: MCP-Atlas Public | AS1: tau3-Bench | AT1: MM Claw | AU1: MLE Bench Lite | AV1: CyberGym
A2: ChatGPT 5.5 | N2: OpenAI - Introducing GPT-5.5 | P2: OpenAI - Introducing GPT-5.5; BenchLM - SWE-bench Pro leaderboard | AB2: OpenAI - Introducing GPT-5.5 | AC2: OpenAI - Introducing GPT-5.5 | AG2: OpenAI - Introducing GPT-5.5 | AL2: OpenAI - Introducing GPT-5.5 | AM2: OpenAI - Introducing GPT-5.5 | AP2: OpenAI - Introducing GPT-5.5 | AV2: OpenAI - Introducing GPT-5.5
A3: ChatGPT 5.3 Codex | N3: OpenAI - Introducing GPT-5.3-Codex | P3: OpenAI - Introducing GPT-5.3-Codex; BenchLM - SWE-bench Pro leaderboard | S3: OpenAI - Introducing GPT-5.3-Codex | AG3: OpenAI - Introducing GPT-5.3-Codex | AL3: OpenAI - Introducing GPT-5.3-Codex | AV3: OpenAI - Introducing GPT-5.3-Codex
A4: Claude Opus 4.7 | N4: OpenAI - Introducing GPT-5.5 | O4: Hokai - Claude Opus 4.7 benchmark summary | P4: BenchLM - SWE-bench Pro leaderboard; Hokai - Claude Opus 4.7 benchmark summary | W4: Hokai - Claude Opus 4.7 benchmark summary | X4: LayerLens - Claude Opus 4.7 on AIME 2026 | AB4: OpenAI - Introducing GPT-5.5 | AC4: OpenAI - Introducing GPT-5.5 | AE4: Hokai - Claude Opus 4.7 benchmark summary | AG4: OpenAI - Introducing GPT-5.5 | AH4: Artificial Analysis - Opus 4.7 analysis | AL4: OpenAI - Introducing GPT-5.5; Hokai - Claude Opus 4.7 benchmark summary | AM4: OpenAI - Introducing GPT-5.5 | AR4: Hokai - Claude Opus 4.7 benchmark summary | AV4: OpenAI - Introducing GPT-5.5
A5: Claude Sonnet 4.6 | N5: Anthropic - Introducing Claude Sonnet 4.6 and system card | O5: Anthropic - Introducing Claude Sonnet 4.6 and system card | AH5: Artificial Analysis - Opus 4.7 analysis
A6: MiniMax M2.7 | N6: NVIDIA NIM - MiniMax M2.7 model card | P6: NVIDIA NIM - MiniMax M2.7 model card; BenchLM - SWE-bench Pro leaderboard | Q6: NVIDIA NIM - MiniMax M2.7 model card | R6: NVIDIA NIM - MiniMax M2.7 model card | T6: NVIDIA NIM - MiniMax M2.7 model card | U6: NVIDIA NIM - MiniMax M2.7 model card | AH6: NVIDIA NIM - MiniMax M2.7 model card | AP6: NVIDIA NIM - MiniMax M2.7 model card | AT6: NVIDIA NIM - MiniMax M2.7 model card | AU6: NVIDIA NIM - MiniMax M2.7 model card
A7: Kimi K2.6 | K7: Moonshot AI - Kimi K2.6 Hugging Face model card | L7: Moonshot AI - Kimi K2.6 Hugging Face model card | M7: Moonshot AI - Kimi K2.6 Hugging Face model card | N7: Moonshot AI - Kimi K2.6 Hugging Face model card | O7: Moonshot AI - Kimi K2.6 Hugging Face model card | P7: Moonshot AI - Kimi K2.6 Hugging Face model card; BenchLM - SWE-bench Pro leaderboard | Q7: Moonshot AI - Kimi K2.6 Hugging Face model card | W7: Moonshot AI - Kimi K2.6 Hugging Face model card | X7: Moonshot AI - Kimi K2.6 Hugging Face model card | Z7: Moonshot AI - Kimi K2.6 Hugging Face model card | AA7: Moonshot AI - Kimi K2.6 Hugging Face model card | AD7: Moonshot AI - Kimi K2.6 Hugging Face model card | AE7: Moonshot AI - Kimi K2.6 Hugging Face model card | AH7: DeepSeek - DeepSeek-V4-Pro Hugging Face model card | AL7: Moonshot AI - Kimi K2.6 Hugging Face model card | AM7: Moonshot AI - Kimi K2.6 Hugging Face model card | AO7: Moonshot AI - Kimi K2.6 Hugging Face model card | AP7: Moonshot AI - Kimi K2.6 Hugging Face model card
A8: DeepSeek V4-Pro Max | B8: DeepSeek - DeepSeek-V4-Pro Hugging Face model card | C8: DeepSeek - DeepSeek-V4-Pro Hugging Face model card | D8: DeepSeek - DeepSeek-V4-Pro Hugging Face model card | E8: DeepSeek - DeepSeek-V4-Pro Hugging Face model card | F8: DeepSeek - DeepSeek-V4-Pro Hugging Face model card | K8: DeepSeek - DeepSeek-V4-Pro Hugging Face model card | N8: DeepSeek - DeepSeek-V4-Pro Hugging Face model card | O8: DeepSeek - DeepSeek-V4-Pro Hugging Face model card | P8: DeepSeek - DeepSeek-V4-Pro Hugging Face model card; BenchLM - SWE-bench Pro leaderboard | Q8: DeepSeek - DeepSeek-V4-Pro Hugging Face model card | V8: DeepSeek - DeepSeek-V4-Pro Hugging Face model card | W8: DeepSeek - DeepSeek-V4-Pro Hugging Face model card | Z8: DeepSeek - DeepSeek-V4-Pro Hugging Face model card | AA8: DeepSeek - DeepSeek-V4-Pro Hugging Face model card | AD8: DeepSeek - DeepSeek-V4-Pro Hugging Face model card | AE8: DeepSeek - DeepSeek-V4-Pro Hugging Face model card | AH8: DeepSeek - DeepSeek-V4-Pro Hugging Face model card | AM8: DeepSeek - DeepSeek-V4-Pro Hugging Face model card | AP8: DeepSeek - DeepSeek-V4-Pro Hugging Face model card | AR8: DeepSeek - DeepSeek-V4-Pro Hugging Face model card
A9: GLM-5.1 | N9: NVIDIA NIM - GLM-5.1 model card | P9: NVIDIA NIM - GLM-5.1 model card; BenchLM - SWE-bench Pro leaderboard | T9: NVIDIA NIM - GLM-5.1 model card | W9: NVIDIA NIM - GLM-5.1 model card | X9: NVIDIA NIM - GLM-5.1 model card | Y9: NVIDIA NIM - GLM-5.1 model card | Z9: NVIDIA NIM - GLM-5.1 model card | AA9: NVIDIA NIM - GLM-5.1 model card | AD9: NVIDIA NIM - GLM-5.1 model card | AE9: NVIDIA NIM - GLM-5.1 model card | AH9: DeepSeek - DeepSeek-V4-Pro Hugging Face model card | AM9: NVIDIA NIM - GLM-5.1 model card | AN9: NVIDIA NIM - GLM-5.1 model card | AQ9: NVIDIA NIM - GLM-5.1 model card | AR9: NVIDIA NIM - GLM-5.1 model card | AS9: NVIDIA NIM - GLM-5.1 model card | AV9: NVIDIA NIM - GLM-5.1 model card

Sheet All Scores
A1: Category | B1: Benchmark | C1: Model | D1: Score | E1: Unit | F1: Source ID | G1: Source Name | H1: Note
A2: Coding | B2: SWE-Bench Pro | C2: ChatGPT 5.5 | D2: 58.6 | E2: % resolved | F2: openai_gpt55; benchlm_swepro | G2: OpenAI - Introducing GPT-5.5; BenchLM - SWE-bench Pro leaderboard | H2: Real GitHub issue resolution.
A3: Coding | B3: Terminal-Bench 2.0 | C3: ChatGPT 5.5 | D3: 82.7 | E3: % accuracy | F3: openai_gpt55 | G3: OpenAI - Introducing GPT-5.5 | H3: Command-line engineering workflows.
A4: Writing & Knowledge | B4: GDPval | C4: ChatGPT 5.5 | D4: 84.9 | E4: % wins or ties | F4: openai_gpt55 | G4: OpenAI - Introducing GPT-5.5 | H4: Knowledge-work tasks across occupations.
A5: Agentic & Other | B5: OSWorld-Verified | C5: ChatGPT 5.5 | D5: 78.7 | E5: % success | F5: openai_gpt55 | G5: OpenAI - Introducing GPT-5.5 | H5: Computer-use productivity tasks.
A6: Agentic & Other | B6: Toolathlon | C6: ChatGPT 5.5 | D6: 55.6 | E6: % pass | F6: openai_gpt55 | G6: OpenAI - Introducing GPT-5.5 | H6: Tool-use benchmark.
A7: Agentic & Other | B7: BrowseComp | C7: ChatGPT 5.5 | D7: 84.4 | E7: % pass | F7: openai_gpt55 | G7: OpenAI - Introducing GPT-5.5 | H7: Difficult web browsing and retrieval.
A8: Math & Reasoning | B8: FrontierMath Tier 1-3 | C8: ChatGPT 5.5 | D8: 51.7 | E8: % pass | F8: openai_gpt55 | G8: OpenAI - Introducing GPT-5.5 | H8: Advanced frontier math.
A9: Math & Reasoning | B9: FrontierMath Tier 4 | C9: ChatGPT 5.5 | D9: 35.4 | E9: % pass | F9: openai_gpt55 | G9: OpenAI - Introducing GPT-5.5 | H9: Harder frontier math tier.
A10: Agentic & Other | B10: CyberGym | C10: ChatGPT 5.5 | D10: 81.8 | E10: % score | F10: openai_gpt55 | G10: OpenAI - Introducing GPT-5.5 | H10: Cybersecurity challenge suite.
A11: Coding | B11: SWE-Bench Pro | C11: ChatGPT 5.3 Codex | D11: 56.8 | E11: % resolved | F11: openai_gpt53_codex; benchlm_swepro | G11: OpenAI - Introducing GPT-5.3-Codex; BenchLM - SWE-bench Pro leaderboard | H11: Real GitHub issue resolution.
A12: Coding | B12: Terminal-Bench 2.0 | C12: ChatGPT 5.3 Codex | D12: 77.3 | E12: % accuracy | F12: openai_gpt53_codex | G12: OpenAI - Introducing GPT-5.3-Codex | H12: Command-line engineering workflows.
A13: Agentic & Other | B13: OSWorld-Verified | C13: ChatGPT 5.3 Codex | D13: 64.7 | E13: % success | F13: openai_gpt53_codex | G13: OpenAI - Introducing GPT-5.3-Codex | H13: Computer-use productivity tasks.
... A98: Writing & Knowledge | B98: GDPval-AA | C98: GLM-5.1 | D98: 1535 | E98: Elo | F98: deepseek_hf | G98: DeepSeek - DeepSeek-V4-Pro Hugging Face model card | H98: DeepSeek comparison table.

Sheet Benchmark Charts
A1: GSM8K | 1 - Starter math
A2: Model | B2: Score | C2: Unit | D2: Source
A3: DeepSeek V4-Pro Max | B3: 92.6 | C3: % EM | D3: DeepSeek - DeepSeek-V4-Pro Hugging Face model card
A13: What is
A14: Grade-school arithmetic word problems.
A18: Explain for 11
A19: Story problems: read the sentence, set up the numbers, and calculate the answer.
A23: Top-score example
A24: Top available score here: DeepSeek V4-Pro Max at 92.6 % EM. At that level, the model is solving multi-step school word problems with clean arithmetic.
A28: Similar tests and differences
A29: Easier than MATH, AIME, HMMT, and IMO-style tests.
A35: HumanEval | 1 - Starter coding
A36: Model | B36: Score | C36: Unit | D36: Source
A37: DeepSeek V4-Pro Max | B37: 76.8 | C37: % pass@1 | D37: DeepSeek - DeepSeek-V4-Pro Hugging Face model card
A47: What is
A48: Small Python function-writing tasks checked by hidden tests.
A52: Explain for 11
A53: Write one short function, then the computer tries secret examples to see if it works.
A57: Top-score example
A58: Top available score here: DeepSeek V4-Pro Max at 76.8 % pass@1. At that level, the model is solving basic Python functions such as list cleanup, string logic, or simple algorithms.
A62: Similar tests and differences
A63: Simpler and older than LiveCodeBench; much smaller than SWE-Bench.
A69: SimpleQA-Verified | 1 - Starter facts
A70: Model | B70: Score | C70: Unit | D70: Source
A71: DeepSeek V4-Pro Max | B71: 57.9 | C71: % pass | D71: DeepSeek - DeepSeek-V4-Pro Hugging Face model card
A81: What is
A82: Short factual questions with verified answers.
A86: Explain for 11
A87: A fact-check quiz: answer clearly and do not make things up.
A91: Top-score example
A92: Top available score here: DeepSeek V4-Pro Max at 57.9 % pass. At that level, the model is solving straight factual questions where accuracy matters more than style.
A96: Similar tests and differences
A97: Unlike BrowseComp, the answer should not require a long web hunt.
A103: MATH | 2 - School contest math
A104: Model | B104: Score | C104: Unit | D104: Source
A105: DeepSeek V4-Pro Max | B105: 64.5 | C105: % EM | D105: DeepSeek - DeepSeek-V4-Pro Hugging Face model card
A115: What is
A116: Competition-style math problems covering algebra, geometry, counting, and number theory.
A120: Explain for 11
A121: Hard school math puzzles where one missed step ruins the answer.
...

Sheet Benchmark Guide
A1: Benchmark | B1: Category | C1: Difficulty Ladder | D1: What is | E1: Explain for 11 | F1: Top-score example | G1: Similar tests and differences | H1: Top score note
A2: GSM8K | B2: Math & Reasoning | C2: 1 - Starter math | D2: Grade-school arithmetic word problems. | E2: Story problems: read the sentence, set up the numbers, and calculate the answer. | F2: multi-step school word problems with clean arithmetic | G2: Easier than MATH, AIME, HMMT, and IMO-style tests. | H2: Top available score here: DeepSeek V4-Pro Max at 92.6 % EM. At that level, the model is solving multi-step school word problems with clean arithmetic.
A3: HumanEval | B3: Coding | C3: 1 - Starter coding | D3: Small Python function-writing tasks checked by hidden tests. | E3: Write one short function, then the computer tries secret examples to see if it works. | F3: basic Python functions such as list cleanup, string logic, or simple algorithms | G3: Simpler and older than LiveCodeBench; much smaller than SWE-Bench. | H3: Top available score here: DeepSeek V4-Pro Max at 76.8 % pass@1. At that level, the model is solving basic Python functions such as list cleanup, string logic, or simple algorithms.
A4: SimpleQA-Verified | B4: Math & Reasoning | C4: 1 - Starter facts | D4: Short factual questions with verified answers. | E4: A fact-check quiz: answer clearly and do not make things up. | F4: straight factual questions where accuracy matters more than style | G4: Unlike BrowseComp, the answer should not require a long web hunt. | H4: Top available score here: DeepSeek V4-Pro Max at 57.9 % pass. At that level, the model is solving straight factual questions where accuracy matters more than style.
A5: MATH | B5: Math & Reasoning | C5: 2 - School contest math | D5: Competition-style math problems covering algebra, geometry, counting, and number theory. | E5: Hard school math puzzles where one missed step ruins the answer. | F5: contest math that needs several steps, not just arithmetic | G5: Harder than GSM8K; easier than AIME/HMMT/IMO and FrontierMath. | H5: Top available score here: DeepSeek V4-Pro Max at 64.5 % EM. At that level, the model is solving contest math that needs several steps, not just arithmetic.
A6: MMLU-Pro | B6: Math & Reasoning | C6: 2 - Broad knowledge | D6: A harder version of MMLU with professional and academic multiple-choice questions. | E6: A big quiz across school and work subjects, but the questions try to trick shallow guessing. | F6: multi-subject reasoning across science, law, medicine, and humanities | G6: Broader than GPQA, which focuses on expert science. | H6: Top available score here: DeepSeek V4-Pro Max at 87.5 % EM. At that level, the model is solving multi-subject reasoning across science, law, medicine, and humanities.
A7: MMMLU | B7: Writing & Knowledge | C7: 2 - Multilingual knowledge | D7: A multilingual MMLU-style benchmark for knowledge across languages. | E7: The same big school quiz idea, but not only in English. | F7: knowledge questions in multiple languages | G7: Related to GMMLU and MILU; these compare language coverage more than coding power. | H7: No comparable public score is recorded in this workbook yet. The guide entry is included so you can track it when a model card or leaderboard publishes scores.
A8: GMMLU English | B8: Writing & Knowledge | C8: 2 - Multilingual knowledge | D8: The English slice of a global MMLU-style benchmark. | E8: The English version of a world knowledge quiz. | F8: English-language academic and professional knowledge questions | G8: Use beside low-resource averages to see whether a model is only strong in major languages. | H8: No comparable public score is recorded in this workbook yet. The guide entry is included so you can track it when a model card or leaderboard publishes scores.
A9: GMMLU low-resource average | B9: Writing & Knowledge | C9: 2 - Multilingual knowledge | D9: Average performance across lower-resource languages. | E9: A test of whether the AI still helps in languages with less training data online. | F9: knowledge questions in languages with fewer public training examples | G9: More about language fairness than raw reasoning difficulty. | H9: No comparable public score is recorded in this workbook yet. The guide entry is included so you can track it when a model card or leaderboard publishes scores.
A10: MILU average | B10: Writing & Knowledge | C10: 2 - Multilingual knowledge | D10: A multilingual language-understanding average. | E10: Another world-language report card for general knowledge. | F10: general knowledge and reasoning across languages | G10: Similar to GMMLU; compare exact datasets before ranking models. | H10: No comparable public score is recorded in this workbook yet. The guide entry is included so you can track it when a model card or leaderboard publishes scores.
A11: LiveCodeBench v6 | B11: Coding | C11: 2 - Current coding | D11: Fresh programming contest-style tasks designed to reduce memorization. | E11: A newer coding contest where the model cannot just remember old answers. | F11: algorithmic coding problems with hidden tests | G11: More current than HumanEval; not as project-like as SWE-Bench. | H11: Top available score here: DeepSeek V4-Pro Max at 93.5 % pass. At that level, the model is solving algorithmic coding problems with hidden tests.
A12: OJBench Python | B12: Coding | C12: 2 - Current coding | D12: Online-judge Python programming tasks. | E12: Coding contest puzzles where the answer must pass lots of hidden cases. | F12: Python algorithm puzzles with strict pass/fail tests | G12: Close to LiveCodeBench, but focused on online-judge style Python. | H12: Top available score here: Kimi K2.6 at 60.6 % pass. At that level, the model is solving Python algorithm puzzles with strict pass/fail tests.
... A48: CyberGym | B48: Agentic & Other | C48: 5 - Cybersecurity | D48: Cybersecurity challenge tasks. | E48: A computer-security obstacle course for finding and fixing digital weaknesses. | F48: security tasks such as vulnerability analysis and challenge solving | G48: Specialized domain test; not a general writing or math benchmark. | H48: Top available score here: ChatGPT 5.5 at 81.8 % score. At that level, the model is solving security tasks such as vulnerability analysis and challenge solving.

Sheet Similar Tests
A1: Family | B1: How to tell them apart
A2: SWE-Bench family | B2: Verified is the cleaner human-checked set. Pro is harder and better for top coding agents. Multilingual checks non-Python codebases. Multi SWE and NL2Repo move closer to broad repository work.
A3: Coding puzzle family | B3: HumanEval is the small starter set. OJBench and LiveCodeBench are current contest-style coding. SciCode adds science formulas. Codeforces is a rating, not a percent score.
A4: Math ladder | B4: GSM8K is the easy entry. MATH is contest practice. AIME is elite high-school math. HMMT and IMO-style tasks are harder. FrontierMath is the boss level.
A5: Knowledge and expert reasoning | B5: MMLU-Pro is broad. GPQA-Diamond is deep expert science. HLE is broad and extreme. SimpleQA checks short factual reliability.
A6: Professional work | B6: GDPval measures office and professional tasks as wins/ties. GDPval-AA uses Elo. Finance Agent narrows the lens to finance workflows.
A7: Tool and agent tests | B7: Toolathlon and Tool-Decathlon ask whether tools are chosen correctly. MCP-Atlas asks whether connected tools are orchestrated. tau3-Bench adds conversation and policy constraints.
A8: Web research | B8: BrowseComp is a hard web treasure hunt. DeepSearchQA is search-heavy question answering. BrowseComp with context management stresses remembering and organizing evidence.
A9: Multimodal and multilingual | B9: MMMU-Pro adds images and diagrams. MMMU-Pro with tools allows external help. MMMLU, GMMLU, and MILU ask whether knowledge works across languages.

Sheet Sources
A1: ID | B1: Source | C1: URL | D1: Used for
A2: openai_gpt55 | B2: OpenAI - Introducing GPT-5.5 | C2: https://openai.com/index/introducing-gpt-5-5/ | D2: ChatGPT 5.5 / GPT-5.5 coding, agentic, knowledge-work, math, and cyber scores.
A3: openai_gpt53_codex | B3: OpenAI - Introducing GPT-5.3-Codex | C3: https://openai.com/index/introducing-gpt-5-3-codex/ | D3: ChatGPT 5.3 Codex / GPT-5.3-Codex coding, OSWorld, GDPval, CyberGym, and SWE-Lancer scores.
A4: anthropic_sonnet46 | B4: Anthropic - Introducing Claude Sonnet 4.6 and system card | C4: https://www.anthropic.com/news/claude-sonnet-4-6 | D4: Sonnet 4.6 launch context and Anthropic-reported SWE-bench Verified / Terminal-Bench values.
A5: anthropic_opus47 | B5: Anthropic - Introducing Claude Opus 4.7 | C5: https://www.anthropic.com/news/claude-opus-4-7 | D5: Opus 4.7 launch context and customer benchmark notes.
A6: benchlm_swepro | B6: BenchLM - SWE-bench Pro leaderboard | C6: https://benchlm.ai/benchmarks/swePro | D6: Current SWE-bench Pro leaderboard including Opus 4.7, ChatGPT 5.5, Kimi K2.6, GLM-5.1, ChatGPT 5.3 Codex, MiniMax M2.7, and DeepSeek V4-Pro Max.
A7: kimi_hf | B7: Moonshot AI - Kimi K2.6 Hugging Face model card | C7: https://huggingface.co/moonshotai/Kimi-K2.6 | D7: Kimi K2.6 model summary and evaluation table.
A8: deepseek_hf | B8: DeepSeek - DeepSeek-V4-Pro Hugging Face model card | C8: https://huggingface.co/deepseek-ai/DeepSeek-V4-Pro | D8: DeepSeek V4-Pro Max comparison table and evaluation results.
A9: deepseek_transparency | B9: DeepSeek Transparency Center | C9: https://www.deepseek.com/en/transparency/ | D9: Confirmed latest DeepSeek V4 release naming and release date.
A10: glm_nvidia | B10: NVIDIA NIM - GLM-5.1 model card | C10: https://build.nvidia.com/z-ai/glm-5.1/modelcard | D10: GLM-5.1 coding, math, and tool-use scores.
A11: minimax_nvidia | B11: NVIDIA NIM - MiniMax M2.7 model card | C11: https://docs.api.nvidia.com/nim/reference/minimaxai-minimax-m2.7 | D11: MiniMax M2.7 coding, productivity, tool-use, and ML competition scores.
A12: aa_opus47 | B12: Artificial Analysis - Opus 4.7 analysis | C12: https://artificialanalysis.ai/articles/opus-4-7-everything-you-need-to-know/ | D12: Opus 4.7 GDPval-AA Elo and Artificial Analysis Intelligence Index context.
... A14: layerlens_opus47_aime | B14: LayerLens - Claude Opus 4.7 on AIME 2026 | C14: https://layerlens.ai/blog/claude-opus-4-7-aime2026 | D14: Opus 4.7 AIME 2026 independent/aggregated benchmark entry.
